Workbook

Sheet 1. Dashboard
A1: FABRINET (NYSE: FN) — SHORT THESIS
A2: Executive Dashboard | Price $386.64 (2026-09-18) | Position: SHORT | UChicago AI-Enabled Investing Competition
A4: KEY METRICS (blue = external market data (Yahoo, 2026-09-18) or linked filing data; see cited tab)
A5: Metric | B5: Value | D5: Metric | E5: Value
A6: Current price | B6: $386.64 | D6: FY2026 EBITDA ($mm) | E6: ='2. Historical Financials'!F32
A7: Market capitalization ($mm) | B7: 14070 | D7: FY2026 EPS, diluted ($) | E7: ='2. Historical Financials'!F18
A8: Enterprise value ($mm) | B8: 13200 | D8: FY2026 FCF ($mm, cash-paid basis) | E8: ='2. Historical Financials'!F26
A9: FY2026 Revenue ($mm) | B9: ='2. Historical Financials'!F6 | D9: FY2026 FCF margin % | E9: ='2. Historical Financials'!F28
A11: Metric | B11: Value | D11: Metric | E11: Value
A12: FY2027 consensus revenue ($mm) | B12: 6090 | D12: EV / Revenue (FY26A) | E12: =13200.0/'2. Historical Financials'!F6
A13: FY2027 consensus EPS ($) | B13: 18.16 | D13: Forward P/E (FY27E) | E13: =386.64/B13
A14: FY2028E consensus revenue | B14: N/A — not independently verifiable as genuine polled consensus (see Tab 10) | D14: EV / EBITDA (Yahoo-stated / independently calc'd) | E14: 21.17x stated / 24.87x calc'd (unreconciled)
A15: FY2028E consensus EPS | B15: N/A — not independently verifiable as genuine polled consensus (see Tab 10) | D15: FCF yield (FY26A, cash-paid basis) | E15: ='2. Historical Financials'!F26/14070.0
A17: BULL / CONSENSUS / BEAR VALUATION SUMMARY (FY2029E; linked live from Tab 11 & Tab 12)
A18: Scenario | B18: Revenue ($mm) | C18: Growth % | D18: Gross margin % | E18: Op. margin % | F18: EPS ($) | G18: FCF ($mm) | H18: Mult. | I18: Price target | J18: Upside/downside
A19: BEAR | B19: ='11. Scenario Model'!D22 | C19: ='11. Scenario Model'!D22/'2. Historical Financials'!F6-1 | D19: ='11. Scenario Model'!B13 | E19: ='11. Scenario Model'!D25 | F19: ='11. Scenario Model'!D27 | G19: ='11. Scenario Model'!D32 | H19: ='12. Valuation'!B9 | I19: ='12. Valuation'!B10 | J19: ='12. Valuation'!B11
A20: BASE / Consensus-anchored | B20: ='11. Scenario Model'!D48 | C20: ='11. Scenario Model'!D48/'2. Historical Financials'!F6-1 | D20: ='11. Scenario Model'!B39 | E20: ='11. Scenario Model'!D51 | F20: ='11. Scenario Model'!D53 | G20: ='11. Scenario Model'!D58 | H20: ='12. Valuation'!C9 | I20: ='12. Valuation'!C10 | J20: ='12. Valuation'!C11
A21: BULL | B21: ='11. Scenario Model'!D74 | C21: ='11. Scenario Model'!D74/'2. Historical Financials'!F6-1 | D21: ='11. Scenario Model'!B65 | E21: ='11. Scenario Model'!D77 | F21: ='11. Scenario Model'!D79 | G21: ='11. Scenario Model'!D84 | H21: ='12. Valuation'!D9 | I21: ='12. Valuation'!D10 | J21: ='12. Valuation'!D11
A23: Gross margin, operating margin, EPS, FCF and revenue growth all flow from the EDITABLE assumption cells on Tab 11 — change any yellow cell there and this table updates automatically. Price target = FY2029E EPS × selected P/E multiple (Tab 12).
A25: MAJOR ASSUMPTIONS DRIVING THE BEAR CASE (from Tab 11, historical-range-derived, not invented)
A26: • Revenue growth 9.0% — the LOWEST of FN's own 4 disclosed YoY growth observations (FY23-26), i.e. no further AI-cycle acceleration assumed.
A27: • Gross margin 12.0% — held at FY2026's actual (already-depressed) level, the low end of the 5-year range.
A28: • Capex/Revenue 5.47% — held at FY2026's actual (already-elevated) level, the high end of the 5-year range.
A29: • Working-capital plug −23.3% of ΔRevenue — the WORST of FN's own 4 disclosed observations (FY23-26), i.e. the FY2026 cash-conversion problem is assumed to persist, not to normalize.
A30: • P/E multiple 18x (assumption) — below the current 30.09x trailing P/E, reflecting further compression consistent with the reverse-DCF finding that today's price still requires an unprecedented sustained FCF margin.
A32: 1. SHORT THESIS
A33: Fabrinet trades like an AI/datacenter compounder (EV/EBITDA ~21-25x, up to 38x in Mar-2026) but its own filings show a commodity-margin contract manufacturer: gross margin has NOT expanded despite the AI buildout (12.7% FY23 peak → 12.0% FY26), and FY2026 net income of $473.0mm produced only ~$3-4mm of conventional free cash flow (cash-paid capex basis) — a collapse driven by inventory nearly doubling (+75.8%) and a capex ramp from $47.5mm to $252.5mm cash-paid over two years. Management itself took on FN's first new debt in years ($75mm, Aug-2026) to keep funding the buildout.
A35: 2. KEY CATALYSTS
A36: Next 1-2 quarterly prints (Nov-2026, ~Feb-2027) showing whether gross margin stays stuck near 12% and FCF stays near zero despite continued revenue growth; FY2027 capex guided to increase FURTHER per MD&A; inventory/DIO trend; any second sell-side downgrade citing FCF/margin specifically (not just valuation, as JPMorgan's Apr-2026 downgrade did).
A38: 3. MAJOR RISKS
... A45: Gross margin inflecting upward 100bp+ for two consecutive quarters despite rising mix (would break the no-pricing-power pillar); FCF (cash-paid basis) recovering toward FY2024's ~12.6% margin within 2-3 quarters (would break the cash-conversion pillar); revenue growth sustaining well above the Bear-case 9% floor while margin/FCF simultaneously improve (would confirm the bull re-rating case rather than the short).

Sheet 0. Legend & Cover
A1: FABRINET (NYSE: FN) — SHORT THESIS MODEL
A2: Institutional working model — built exclusively from SEC filings, with market data separately tagged
A4: HOW TO READ THIS WORKBOOK
A5: Blue text | B5: REPORTED FACT — hardcoded, taken directly from a 10-K, 10-Q, or (where labeled) external market data. Never a calculation.
A6: Black text | B6: MECHANICALLY DERIVED — an Excel formula computed from reported facts elsewhere in this workbook (e.g. margin %, YoY growth, FCF).
A7: Orange text on yellow fill | B7: ASSUMPTION — an editable input you can change. Changing it recalculates every downstream formula automatically.
A8: Grey italic ‘N/A’ | B8: Not disclosed in the filings retrieved for this model. Never filled with an estimate.
A10: SOURCE ABBREVIATIONS USED THROUGHOUT
A11: 10K26 | B11: Fabrinet Form 10-K for FY2026 (fiscal year ended June 26, 2026), filed 2026-08-18, SEC accession 0001408710-26-000028. Contains audited comparatives for FY2025 and FY2024.
A12: 10K24 | B12: Fabrinet Form 10-K for FY2024 (fiscal year ended June 28, 2024), filed 2024-08-20, SEC accession 0001408710-24-000032. Contains audited comparatives for FY2023 and FY2022.
A13: 10Q | B13: Fabrinet Form 10-Q for the quarter ended March 27, 2026, SEC accession 0001408710-26-000016.
A14: YHOO | B14: Yahoo Finance (finance.yahoo.com/quote/FN and /key-statistics), accessed 2026-09-18. EXTERNAL MARKET DATA — not a filing.
A15: ANALYST | B15: Cross-verified sell-side analyst actions gathered via web research 2026-09-18; each row individually sourced (see Tab 9).
A16: CONSENSUS | B16: Cross-verified consensus estimate aggregators (stockanalysis.com, MarketBeat, Investing.com), accessed 2026-09-18; see Tab 10 for per-figure sourcing.
A18: MODELING CONSTRAINTS APPLIED
A19: • Historical tabs (2,3,5,6,7,8) use ONLY figures explicitly reported in the 10-K/10-Q filings listed above. No analyst consensus, no invented growth rates, no backfilled numbers.
A20: • Where the same metric is defined two ways within a filing (e.g. accrual-basis vs. cash-paid capex), BOTH are shown, labeled, and not silently reconciled.
A21: • Where Fabrinet changed its segment-reporting categories (twice), all three regimes are shown side-by-side rather than force-mapped onto one another.
A22: • Tabs 9 (Sell-Side Research) and 10 (Consensus Estimates) necessarily use external, non-filing data — this is unavoidable since no 10-K/10-Q discloses analyst targets or forward consensus. Every figure there is individually sourced and dated.
A23: • The Scenario Model (Tab 11) and Valuation (Tab 12) use assumption cells seeded from historical filing ranges (min/avg/max), never from an invented industry CAGR. WACC and terminal growth are NOT derived from filings — they are left as editable external-input cells with a sensitivity grid, per instruction, rather than a single asserted ‘correct’ value.
A25: Prepared for: UChicago AI-Enabled Investing Competition, Round 1 | Position: SHORT Fabrinet (FN) | Model date: 2026-09-18

Sheet 2. Historical Financials
A1: 2. HISTORICAL FINANCIALS
A2: Fiscal years ended late June. $ in millions except per-share data. FY2022–FY2024 from 10K24; FY2025–FY2026 from 10K26.
B4: FY2022 | C4: FY2023 | D4: FY2024 | E4: FY2025 | F4: FY2026 | G4: Source / Logic
A5: INCOME STATEMENT
A6: Revenue | B6: 2262.224 | C6: 2645.237 | D6: 2882.967 | E6: 3419.327 | F6: 4641.097 | G6: 10K24 p.42 (FY22-24) / 10K26 p.44 (FY25-26)
A7: YoY growth % | B7: n/a (no FY21) | C7: =C6/B6-1 | D7: =D6/C6-1 | E7: =E6/D6-1 | F7: =F6/E6-1 | G7: Derived: Rev(t)/Rev(t-1)-1
A8: Cost of revenue | B8: -1983.63 | C8: -2308.964 | D8: -2526.849 | E8: -3005.978 | F8: -4084.586 | G8: 10K24 / 10K26 Results of Operations table
A9: Gross profit | B9: =B6+B8 | C9: =C6+C8 | D9: =D6+D8 | E9: =E6+E8 | F9: =F6+F8 | G9: Derived: Revenue + Cost of revenue (reported separately as 356.118/413.349/556.511 etc. — ties out)
A10: Gross margin % | B10: =B9/B6 | C10: =C9/C6 | D10: =D9/D6 | E10: =E9/E6 | F10: =F9/F6 | G10: Derived; also directly stated by 10-K as 12.3/12.7/12.4/12.1/12.0%
A11: SG&A | B11: -73.941 | C11: -77.673 | D11: -78.481 | E11: -87.466 | F11: -93.507 | G11: 10K24 / 10K26
A12: R&D (disclosed separately) | B12: Not broken out — FN does not separately disclose R&D on the income statement | C12: Not broken out — FN does not separately disclose R&D on the income statement | D12: Not broken out — FN does not separately disclose R&D on the income statement | E12: Not broken out — FN does not separately disclose R&D on the income statement | F12: Not broken out — FN does not separately disclose R&D on the income statement
A13: Restructuring & other | B13: -0.135 | C13: -6.896 | D13: -0.032 | E13: -1.436 | F13: -0.117 | G13: 10K24 / 10K26
A14: Operating income | B14: =B9+B11+B13 | C14: =C9+C11+C13 | D14: =D9+D11+D13 | E14: =E9+E11+E13 | F14: =F9+F11+F13 | G14: Derived: GP + SG&A + Restructuring
A15: Operating margin % | B15: =B14/B6 | C15: =C14/C6 | D15: =D14/D6 | E15: =E14/E6 | F15: =F14/F6
A16: Net income | B16: 200.38 | C16: 247.913 | D16: 296.181 | E16: 332.527 | F16: 473.027 | G16: 10K24 / 10K26 (includes non-operating items: interest income/expense, FX, other income, tax)
A17: Net margin % | B17: =B16/B6 | C17: =C16/C6 | D17: =D16/D6 | E17: =E16/E6 | F17: =F16/F6
A18: Diluted EPS ($/sh) | B18: N/A — not disclosed in filings provided | C18: N/A — not disclosed in filings provided | D18: 8.1 | E18: 9.17 | F18: 13.05 | G18: 10K26 p.54 (FY24-26). FY22-23 diluted EPS not extracted from 10K24 in this pass.
A19: Basic EPS ($/sh) | B19: N/A — not disclosed in filings provided | C19: N/A — not disclosed in filings provided | D19: 8.17 | E19: 9.23 | F19: 13.21
A20: CASH FLOW
A21: Cash from operations (CFO) | B21: 124.246 | C21: 213.31 | D21: 413.146 | E21: 328.365 | F21: 256.725 | G21: 10K24 / 10K26 Consolidated Statements of Cash Flows
A22: Capex — accrual basis (MD&A table) | B22: 80.462 | C22: 66.712 | D22: 49.27 | E22: 130.658 | F22: 298.921 | G22: 10K24/10K26 MD&A ‘Capital Expenditures’ table — “includes amounts for which payments have been accrued”
A23: Capex — cash-paid (PP&E, from CF stmt) | B23: 89.588 | C23: 61.36 | D23: 47.528 | E23: 121.078 | F23: 252.503 | G23: 10K24/10K26 Statements of Cash Flows, ‘Purchase of property, plant and equipment’
A24: Capex — cash-paid intangibles | B24: 0.995 | C24: 0.911 | D24: 0.889 | E24: 0.738 | F24: 1.181
A25: ⚠ DISCLOSURE NOTE: the two capex bases differ within the SAME filing by definition (accrual includes amounts accrued-but-unpaid). Not reconciled per modeling constraint — both used separately below.
A26: FCF (cash-paid basis) = CFO − cash capex − cash intangibles | B26: =B21-B23-B24 | C26: =C21-C23-C24 | D26: =D21-D23-D24 | E26: =E21-E23-E24 | F26: =F21-F23-F24
A27: FCF (accrual capex basis) = CFO − accrual capex | B27: =B21-B22 | C27: =C21-C22 | D27: =D21-D22 | E27: =E21-E22 | F27: =F21-F22
A28: FCF margin % (cash-paid basis) | B28: =B26/B6 | C28: =C26/C6 | D28: =D26/D6 | E28: =E26/E6 | F28: =F26/F6
A29: FCF / Net income (cash-paid basis) | B29: =B26/B16 | C29: =C26/C16 | D29: =D26/D16 | E29: =E26/E16 | F29: =F26/F16
A30: CFO / Net income | B30: =B21/B16 | C30: =C21/C16 | D30: =D21/D16 | E30: =E21/E16 | F30: =F21/F16
A31: D&A (from CF stmt) | B31: 38.738 | C31: 43.832 | D31: 49.017 | E31: 53.433 | F31: 68.371 | G31: 10K24/10K26 Statements of Cash Flows
A32: EBITDA (derived) = Operating income + D&A | B32: =B14+B31 | C32: =C14+C31 | D32: =D14+D31 | E32: =E14+E31 | F32: =F14+F31
A33: BALANCE SHEET / WORKING CAPITAL
A34: Cash and cash equivalents | B34: N/A — not disclosed in filings provided | C34: 231.368 | D34: 409.973 | E34: 306.425 | F34: 346.711 | G34: 10K24/10K26 Balance Sheet. FY22 not shown (10-K balance sheet presents only 2 yrs).
A35: Short-term investments | B35: N/A — not disclosed in filings provided | C35: 319.1 | D35: 448.63 | E35: 627.819 | F35: 528.344
A36: Memo: cash + ST invest. (MD&A aggregate) | B36: 478.2 | C36: 550.5 | D36: 858.6 | E36: 934.2 | F36: 875.1 | G36: 10K24/10K26 MD&A Liquidity discussion — independently stated aggregate; ties to Cash+ST Inv rows above for FY23-26
A37: Trade accounts receivable, net | B37: N/A — not disclosed in filings provided | C37: 531.767 | D37: 592.452 | E37: 758.894 | F37: 1017.933 | G37: 10K24/10K26 Balance Sheet
A38: Inventories, total | B38: N/A — not disclosed in filings provided | C38: 519.576 | D38: 463.206 | E38: 581.015 | F38: 1021.235
A39: Raw materials | B39: N/A — not disclosed in filings provided | C39: N/A — not disclosed in filings provided | D39: N/A — not disclosed in filings provided | E39: 145.128 | F39: 374.773 | G39: 10K26 Note 10 (FY25-26 only; FY22-24 breakdown not disclosed in 10K24 extract)
A40: Work in progress | B40: N/A — not disclosed in filings provided | C40: N/A — not disclosed in filings provided | D40: N/A — not disclosed in filings provided | E40: 377.736 | F40: 568.3
A41: Finished goods | B41: N/A — not disclosed in filings provided | C41: N/A — not disclosed in filings provided | D41: N/A — not disclosed in filings provided | E41: 33.016 | F41: 30.967
...

Sheet 3. Revenue Mix
A1: 3. REVENUE MIX
A2: Fabrinet changed its segment-reporting categories TWICE. Three non-reconcilable regimes shown separately — REPORTED, not recast/estimated by us.
A4: ⚠ Regimes A, B and C use different, company-defined category boundaries. No crosswalk between them is published by Fabrinet, and none is applied here — do not sum across regimes.
A6: REGIME A — REPORTED, FY2022-FY2024 annual (10K24 p.43): Optical comm. (Datacom+Telecom) / Non-optical (Automotive+Ind.laser+Others)
B7: FY2022 | C7: FY2023 | D7: FY2024 | F7: YoY FY23 | G7: YoY FY24 | H7: % of total FY24 | I7: Contribution to FY24 growth
A8: Datacom | B8: 361.306 | C8: 520.796 | D8: 1150.307 | F8: =C8/B8-1 | G8: =D8/C8-1 | H8: =D8/D13 | I8: =(D8-C8)/(D13-C13)
A9: Telecom | B9: 1421.493 | C9: 1487.551 | D9: 1138.708 | F9: =C9/B9-1 | G9: =D9/C9-1 | H9: =D9/D13 | I9: =(D9-C9)/(D13-C13)
A10: Automotive | B10: 204.407 | C10: 368.581 | D10: 327.188 | F10: =C10/B10-1 | G10: =D10/C10-1 | H10: =D10/D13 | I10: =(D10-C10)/(D13-C13)
A11: Industrial laser | B11: 149.357 | C11: 125.415 | D11: 122.722 | F11: =C11/B11-1 | G11: =D11/C11-1 | H11: =D11/D13 | I11: =(D11-C11)/(D13-C13)
A12: Others | B12: 125.661 | C12: 142.894 | D12: 144.042 | F12: =C12/B12-1 | G12: =D12/C12-1 | H12: =D12/D13 | I12: =(D12-C12)/(D13-C13)
A13: Total revenue (check) | B13: =SUM(B8:B12) | C13: =SUM(C8:C12) | D13: =SUM(D8:D12) | I13: Should tie to Tab 2 revenue: 2262.224 / 2645.237 / 2882.967
A15: REGIME B — REPORTED, quarterly/9-month only (10-Q Q3 FY2026 p.14): Optical (Telecom+Datacom+DCI) / Non-optical (Automotive+HPC+Ind.laser+Others). No full FY2025 annual exists under this regime — not fabricated here.
B16: Q3 FY25 (3mo) | C16: Q3 FY26 (3mo) | D16: 9M FY25 | E16: 9M FY26 | F16: YoY Q3 growth | G16: YoY 9M growth | H16: % of Q3FY26 total | I16: Contribution to Q3 YoY $ growth
A17: Telecom | B17: 302.736 | C17: 431.366 | D17: 776.373 | E17: 1179.334 | F17: =C17/B17-1 | G17: =E17/D17-1 | H17: =C17/C24 | I17: =(C17-B17)/(C17-B17+C18-B18+C19-B19+C20-B20+C22-B22+C23-B23)
A18: Datacom | B18: 251.105 | C18: 260.442 | D18: 879.087 | E18: 811.68 | F18: =C18/B18-1 | G18: =E18/D18-1 | H18: =C18/C24 | I18: =(C18-B18)/(C17-B17+C18-B18+C19-B19+C20-B20+C22-B22+C23-B23)
A19: DCI | B19: 103.39 | C19: 196.896 | D19: 275.236 | E19: 477.176 | F19: =C19/B19-1 | G19: =E19/D19-1 | H19: =C19/C24 | I19: =(C19-B19)/(C17-B17+C18-B18+C19-B19+C20-B20+C22-B22+C23-B23)
A20: Automotive | B20: 129.468 | C20: 115.499 | D20: 336.456 | E20: 354.403 | F20: =C20/B20-1 | G20: =E20/D20-1 | H20: =C20/C24 | I20: =(C20-B20)/(C17-B17+C18-B18+C19-B19+C20-B20+C22-B22+C23-B23)
A21: HPC | B21: N/A (not disclosed that period) | C21: 106.746 | D21: N/A (not disclosed that period) | E21: 207.705 | F21: n/a | G21: n/a | H21: =C21/C24 | I21: N/A — HPC not separately disclosed in Q3 FY25 (folded into 'Others' that quarter)
A22: Industrial laser | B22: 40.464 | C22: 44.171 | D22: 113.332 | E22: 125.282 | F22: =C22/B22-1 | G22: =E22/D22-1 | H22: =C22/C24 | I22: =(C22-B22)/(C17-B17+C18-B18+C19-B19+C20-B20+C22-B22+C23-B23)
A23: Others | B23: 44.636 | C23: 59.173 | D23: 129.151 | E23: 169.729 | F23: =C23/B23-1 | G23: =E23/D23-1 | H23: =C23/C24 | I23: =(C23-B23)/(C17-B17+C18-B18+C19-B19+C20-B20+C22-B22+C23-B23)
A24: Total revenue (check) | C24: =SUM(C17:C23) | E24: =SUM(E17:E23) | I24: Q3FY26 total should tie to Tab-2-style quarterly revenue 1214.293; 9M FY26 to 3325.309
A26: REGIME C — REPORTED, RECAST presentation, FY2024-FY2026 annual (10K26 p.44): Data center / Communications infrastructure / Automotive, Industrial & Other. Fabrinet itself recast FY24-25 under this scheme beginning Q4 FY2026 — not our estimate.
B27: FY2024 | C27: FY2025 | D27: FY2026 | F27: YoY FY25 | G27: YoY FY26 | H27: % of total FY26 | I27: Contribution to FY26 growth
A28: Data center | B28: 1529.693 | C28: 1579.915 | D28: 2225.081 | F28: =C28/B28-1 | G28: =D28/C28-1 | H28: =D28/D31 | I28: =(D28-C28)/(D31-C31)
A29: Communications infrastructure | B29: 767.368 | C29: 1049.397 | D29: 1546.403 | F29: =C29/B29-1 | G29: =D29/C29-1 | H29: =D29/D31 | I29: =(D29-C29)/(D31-C31)
A30: Automotive, Industrial & Other | B30: 585.906 | C30: 790.015 | D30: 869.613 | F30: =C30/B30-1 | G30: =D30/C30-1 | H30: =D30/D31 | I30: =(D30-C30)/(D31-C31)
A31: Total revenue (check) | B31: =SUM(B28:B30) | C31: =SUM(C28:C30) | D31: =SUM(D28:D30) | I31: Should tie to Tab 2 revenue: 2882.967 / 3419.327 / 4641.097
A33: KEY OBSERVATION (from Regime A, the only regime spanning the pre-AI-buildout period): in FY2024, ‘Datacom’ grew +120.9% YoY while ‘Telecom’ FELL -23.4% YoY — management's own MD&A attributes the Datacom surge to “artificial intelligence applications” (10K24 p.43-44, HIGH confidence, directly disclosed). Under Regime C (FY24-26 recast), ‘Data center’ mix was 53.1% of revenue in FY24, fell to 46.2% in FY25, and recovered to only 47.9% in FY26 — LOWER than two years ago. Under Regime B (old-old categories), the true ‘DCI’ line is only 16.2% of Q3 FY26 revenue, and ‘Telecom’ ($431.4mm) was a larger contributor to the Q3 FY26 YoY revenue increase than ‘DCI’ ($196.9mm) or ‘HPC’ ($106.7mm) individually.
A35: Sources: 10K24 = Fabrinet 10-K FY2024, p.43 (Results of Operations, revenue by end market table). 10K26 = Fabrinet 10-K FY2026, p.44. 10Q = Fabrinet 10-Q for Q3 FY2026, p.14 (Note 3, Revenues from contracts with customers).

Sheet 4. AI Exposure
A1: 4. AI EXPOSURE
A2: How much of Fabrinet's growth is genuinely, verifiably AI-related? HIGH = directly disclosed. MEDIUM = strongly inferred. LOW = estimated/speculative — never portrayed as disclosed.
A4: Revenue category | B4: Latest disclosed $mm | C4: YoY growth | D4: AI exposure read | E4: Evidence | F4: Confidence
A5: Datacom (Regime A, FY2024) | B5: 1,150.3 (FY24) | C5: +120.9% YoY (FY24 vs FY23) | D5: Direct AI attribution | E5: 10K24 MD&A p.43-44: “increase in revenues from data communication products, primarily for artificial intelligence applications, offset by a decline in revenues from telecommunication products” | F5: HIGH
A6: Datacenter interconnect / DCI (Regime B, Q3 FY26) | B6: 196.9 (Q3 FY26, 3mo) | C6: +90.4% YoY (Q3 FY26 vs Q3 FY25) | D6: DCI modules connect geographically separated data centers — AI/hyperscaler-adjacent by definition, but not 100% attributable to AI workloads specifically (some traditional cloud/enterprise DCI exists too) | E6: 10-Q Note 3, p.14: DCI defined as “opto-electronic modules used to connect two or more geographically separated data centers” | F6: MEDIUM
A7: High-performance computing / HPC (Regime B, Q3 FY26) | B7: 106.7 (Q3 FY26, 3mo) | C7: n/a (not separately disclosed in Q3 FY25 base period) | D7: HPC defined by the company itself as AI-adjacent compute infrastructure | E7: 10-Q Note 3, p.14: “massively parallel computing systems built from interconnected high-performance processors, accelerators, high-speed memory, and low-latency networking” | F7: HIGH (definition) / MEDIUM (full $ attribution, since HPC ≠ 100% AI-specific spend)
A8: NVIDIA-related revenue (estimated $, via disclosed %) | B8: 756.9 (FY26E) = 16.3%×$4,641.1mm | C8: Estimated $ rose FY24→FY26 even as % fell (see Tab 5) | D8: NVIDIA is FN's most AI-identifiable named customer, but FN does not disclose what NVIDIA specifically buys (could include non-AI optical products too) | E8: 10-K Note 21 discloses only the % of revenue, not a $ figure or product mix by customer | F8: MEDIUM (customer name = HIGH; but $ amount and product-level AI attribution = estimated)
A9: Hyperscaler-adjacent (Amazon, disclosed FY26) | B9: 487.3 (FY26E) = 10.5%×$4,641.1mm | C9: New in FY26 (was <10% prior years) | D9: Amazon warrant issued 3/12/2025 explicitly tied to the commercial relationship (10-K Note re: Amazon.com NV Investment Holdings warrant) — strongly suggests a strategic/growth AI-infrastructure relationship, though filings do not confirm AI-specific end use | E9: 10K26 Note re: Warrant issuance to Amazon.com NV Investment Holdings LLC, 381,922 shares | F9: MEDIUM
A10: Telecom (Regime B, Q3 FY26) | B10: 431.4 (Q3 FY26, 3mo) | C10: +42.5% YoY (Q3 FY26 vs Q3 FY25) | D10: Legacy/non-AI category by the company's own definition, yet the single LARGEST dollar contributor to the Q3 FY26 YoY revenue increase (larger than DCI or HPC individually) | E10: 10-Q Note 3, p.14 | F10: HIGH (that it is non-AI-labeled)
A11: Automotive, Industrial laser, Other (Regime A/B) | B11: ~218.8 (Q3 FY26, combined Automotive+Ind.laser+Others, 3mo) | C11: Mixed / roughly flat-to-down | D11: Non-AI by definition | E11: 10-Q Note 3 / 10-K segment tables | F11: HIGH
A13: IMPORTANT: Fabrinet does NOT disclose a single 'AI revenue' figure anywhere in its 10-K or 10-Q. Every row above is either (a) a directly-disclosed category with company-attributed AI language (HIGH), (b) a category whose own definition is AI-adjacent but whose full dollar amount includes some non-AI-specific spend (MEDIUM), or (c) a mechanical estimate from disclosed %'s (MEDIUM, labeled). No LOW-confidence figures are presented as disclosed revenue anywhere in this workbook.
A15: BOTTOM LINE: the cleanest, highest-confidence AI attribution in the filings (Datacom +120.9% in FY24, explicitly linked to AI by management) predates the FY25-26 period this short thesis focuses on. For FY25-26, the strongest AI-adjacent categories (DCI, HPC) are real and growing fast in % terms, but off a small base — Telecom, a category FN itself does not label as AI-related, was the single largest DOLLAR contributor to Fabrinet's most recent quarterly revenue growth.

Sheet 5. Customer Concentration
A1: 5. CUSTOMER CONCENTRATION
A2: All customers ever disclosed at ≥10% of revenue, FY2022-FY2026. Blank = that customer was <10% that year (not zero revenue).
A4: REVENUE CONCENTRATION, % of total revenue — REPORTED FACT (10-K Note 21 / Item 1A)
A5: Customer | B5: FY2022 | C5: FY2023 | D5: FY2024 | E5: FY2025 | F5: FY2026 | G5: Source
A6: Cisco Systems | B6: 0.254 | C6: 0.156 | D6: 0.134 | E6: 0.182 | F6: 0.199 | G6: 10K24 Note21 (FY22-24) / 10K26 Note21 (FY25-26)
A7: NVIDIA | B7: <10% | C7: 0.125 | D7: 0.351 | E7: 0.276 | F7: 0.163 | G7: 10K24 Note21 (FY22-24) / 10K26 Note21 (FY25-26)
A8: Lumentum | B8: 0.103 | C8: 0.154 | D8: <10% | E8: <10% | F8: <10% | G8: 10K24 Note21 (FY22-24) / 10K26 Note21 (FY25-26)
A9: Infinera | B9: 0.125 | C9: 0.124 | D9: <10% | E9: <10% | F9: <10% | G9: 10K24 Note21 (FY22-24) / 10K26 Note21 (FY25-26)
A10: Nokia | B10: <10% | C10: <10% | D10: <10% | E10: <10% | F10: 0.107 | G10: 10K24 Note21 (FY22-24) / 10K26 Note21 (FY25-26)
A11: Amazon.com | B11: <10% | C11: <10% | D11: <10% | E11: <10% | F11: 0.105 | G11: 10K24 Note21 (FY22-24) / 10K26 Note21 (FY25-26)
A12: Sum of customers ≥10% (as stated by 10-K) | B12: 0.482 | C12: 0.559 | D12: 0.485 | E12: 0.458 | F12: 0.574 | G12: FY23-26 directly stated in 10-K text; FY22 = mechanical sum of the 3 named ≥10% customers above (25.4+10.3+12.5)
A13: # customers ≥10% that year | B13: 3 | C13: 4 | D13: 2 | E13: 2 | F13: 4
A15: ACCOUNTS RECEIVABLE CONCENTRATION, % of total trade AR at fiscal year-end — REPORTED FACT (10-K Note 21)
A16: Customer | B16: FY2022 | C16: FY2023 | D16: FY2024 | E16: FY2025 | F16: FY2026 | G16: Source
A17: Cisco Systems | B17: n/a (FY22 AR conc. not disclosed) | C17: <10% | D17: 0.124 | E17: 0.137 | F17: 0.161 | G17: 10K24 Note21 (FY23-24) / 10K26 Note21 (FY25-26)
A18: NVIDIA | B18: n/a (FY22 AR conc. not disclosed) | C18: 0.14 | D18: 0.227 | E18: 0.255 | F18: <10% | G18: 10K24 Note21 (FY23-24) / 10K26 Note21 (FY25-26)
A19: Lumentum | B19: n/a (FY22 AR conc. not disclosed) | C19: 0.137 | D19: <10% | E19: <10% | F19: <10% | G19: 10K24 Note21 (FY23-24) / 10K26 Note21 (FY25-26)
A20: Infinera | B20: n/a (FY22 AR conc. not disclosed) | C20: 0.205 | D20: 0.193 | E20: <10% | F20: <10% | G20: 10K24 Note21 (FY23-24) / 10K26 Note21 (FY25-26)
A21: Nokia | B21: n/a (FY22 AR conc. not disclosed) | C21: <10% | D21: <10% | E21: 0.12 | F21: 0.142 | G21: 10K24 Note21 (FY23-24) / 10K26 Note21 (FY25-26)
A22: Amazon.com | B22: n/a (FY22 AR conc. not disclosed) | C22: <10% | D22: <10% | E22: <10% | F22: 0.115 | G22: 10K24 Note21 (FY23-24) / 10K26 Note21 (FY25-26)
A24: NVIDIA: DID ITS REVENUE ACTUALLY DECLINE, OR DID OTHERS GROW FASTER?
A25: Estimated Nvidia revenue ($mm) = %×Total revenue | B25: <10%, $ not disclosed | C25: =C7*'2. Historical Financials'!C$6 | D25: =D7*'2. Historical Financials'!D$6 | E25: =E7*'2. Historical Financials'!E$6 | F25: =F7*'2. Historical Financials'!F$6 | G25: Derived: disclosed % × total revenue (Tab 2). Company does not disclose the $ figure directly — this is a calculation, not a reported number.
A26: Implied YoY growth in estimated Nvidia $ revenue | B26: n/a | C26: n/a | D26: =IF(OR(NOT(ISNUMBER(D25)),NOT(ISNUMBER(C25))),"n/a",D25/C25-1) | E26: =IF(OR(NOT(ISNUMBER(E25)),NOT(ISNUMBER(D25))),"n/a",E25/D25-1) | F26: =IF(OR(NOT(ISNUMBER(F25)),NOT(ISNUMBER(E25))),"n/a",F25/E25-1)
A28: ANSWER: estimated Nvidia $ revenue rose every year on this calculation (FY24→FY25→FY26), even as its % of total fell (35.1%→27.6%→16.3%). The percentage decline is a MIX effect — Cisco, Nokia and Amazon grew their own $ revenue with Fabrinet even faster than Nvidia's own $ revenue grew — not evidence that Nvidia itself pulled back. This is a mechanical derivation from disclosed %'s × disclosed total revenue, not a company-disclosed $ figure for Nvidia specifically.
A30: TOP-N CONCENTRATION (mechanically derived from the revenue table above)
B31: FY2022 | C31: FY2023 | D31: FY2024 | E31: FY2025 | F31: FY2026 | G31: Note
A32: Top 1 customer % | B32: =MAX(B6:B11) | C32: =MAX(C6:C11) | D32: =MAX(D6:D11) | E32: =MAX(E6:E11) | F32: =MAX(F6:F11)
A33: Top 2 customers % (sum of two largest) | B33: =SUM(LARGE(B6:B11,1),LARGE(B6:B11,2)) | C33: =SUM(LARGE(C6:C11,1),LARGE(C6:C11,2)) | D33: =SUM(LARGE(D6:D11,1),LARGE(D6:D11,2)) | E33: =SUM(LARGE(E6:E11,1),LARGE(E6:E11,2)) | F33: =SUM(LARGE(F6:F11,1),LARGE(F6:F11,2))
A34: Top 4 customers % (= reported sum of all ≥10% names) | B34: =B12 | C34: =C12 | D34: =D12 | E34: =E12 | F34: =F12
A35: YoY change in Top-≥10% concentration, pp | B35: n/a | C35: n/a | D35: =(D34-C34)*100 | E35: =(E34-D34)*100 | F35: =(F34-E34)*100
A37: Sources: 10K24 = Fabrinet 10-K FY2024 Note 21 & Item 1A (p.42, 90). 10K26 = Fabrinet 10-K FY2026 Note 21 & Item 1A (p.6, 90). Chart below plots the reported ‘sum of customers ≥10%’ series.

Sheet 6. Working Capital & FCF
A1: 6. WORKING CAPITAL & FCF
A2: The core evidence tab: how $473mm of FY2026 net income became ~$3-4mm of conventional free cash flow. All figures link back to Tab 2.
A4: SUMMARY (all link to Tab 2 — no re-entry of hardcoded figures)
B5: FY2022 | C5: FY2023 | D5: FY2024 | E5: FY2025 | F5: FY2026 | G5: Source
A6: Revenue | B6: ='2. Historical Financials'!B6 | C6: ='2. Historical Financials'!C6 | D6: ='2. Historical Financials'!D6 | E6: ='2. Historical Financials'!E6 | F6: ='2. Historical Financials'!F6
A7: Net income | B7: ='2. Historical Financials'!B16 | C7: ='2. Historical Financials'!C16 | D7: ='2. Historical Financials'!D16 | E7: ='2. Historical Financials'!E16 | F7: ='2. Historical Financials'!F16
A8: Operating cash flow (CFO) | B8: ='2. Historical Financials'!B21 | C8: ='2. Historical Financials'!C21 | D8: ='2. Historical Financials'!D21 | E8: ='2. Historical Financials'!E21 | F8: ='2. Historical Financials'!F21
A9: Capex (cash-paid, incl. intangibles) | B9: ='2. Historical Financials'!B23+'2. Historical Financials'!B24 | C9: ='2. Historical Financials'!C23+'2. Historical Financials'!C24 | D9: ='2. Historical Financials'!D23+'2. Historical Financials'!D24 | E9: ='2. Historical Financials'!E23+'2. Historical Financials'!E24 | F9: ='2. Historical Financials'!F23+'2. Historical Financials'!F24
A10: FCF (cash-paid basis) | B10: ='2. Historical Financials'!B26 | C10: ='2. Historical Financials'!C26 | D10: ='2. Historical Financials'!D26 | E10: ='2. Historical Financials'!E26 | F10: ='2. Historical Financials'!F26
A11: Inventory (period-end) | B11: ='2. Historical Financials'!B38 | C11: ='2. Historical Financials'!C38 | D11: ='2. Historical Financials'!D38 | E11: ='2. Historical Financials'!E38 | F11: ='2. Historical Financials'!F38
A12: Accounts receivable (period-end) | B12: ='2. Historical Financials'!B37 | C12: ='2. Historical Financials'!C37 | D12: ='2. Historical Financials'!D37 | E12: ='2. Historical Financials'!E37 | F12: ='2. Historical Financials'!F37
A13: Accounts payable (period-end) | B13: ='2. Historical Financials'!B43 | C13: ='2. Historical Financials'!C43 | D13: ='2. Historical Financials'!D43 | E13: ='2. Historical Financials'!E43 | F13: ='2. Historical Financials'!F43
A15: GROWTH RATES (derived)
A16: Revenue growth % | B16: n/a | C16: =IF(OR(NOT(ISNUMBER(C6)),NOT(ISNUMBER(B6))),"n/a",C6/B6-1) | D16: =IF(OR(NOT(ISNUMBER(D6)),NOT(ISNUMBER(C6))),"n/a",D6/C6-1) | E16: =IF(OR(NOT(ISNUMBER(E6)),NOT(ISNUMBER(D6))),"n/a",E6/D6-1) | F16: =IF(OR(NOT(ISNUMBER(F6)),NOT(ISNUMBER(E6))),"n/a",F6/E6-1)
A17: Net income growth % | B17: n/a | C17: =IF(OR(NOT(ISNUMBER(C7)),NOT(ISNUMBER(B7))),"n/a",C7/B7-1) | D17: =IF(OR(NOT(ISNUMBER(D7)),NOT(ISNUMBER(C7))),"n/a",D7/C7-1) | E17: =IF(OR(NOT(ISNUMBER(E7)),NOT(ISNUMBER(D7))),"n/a",E7/D7-1) | F17: =IF(OR(NOT(ISNUMBER(F7)),NOT(ISNUMBER(E7))),"n/a",F7/E7-1)
A18: CFO growth % | B18: n/a | C18: =IF(OR(NOT(ISNUMBER(C8)),NOT(ISNUMBER(B8))),"n/a",C8/B8-1) | D18: =IF(OR(NOT(ISNUMBER(D8)),NOT(ISNUMBER(C8))),"n/a",D8/C8-1) | E18: =IF(OR(NOT(ISNUMBER(E8)),NOT(ISNUMBER(D8))),"n/a",E8/D8-1) | F18: =IF(OR(NOT(ISNUMBER(F8)),NOT(ISNUMBER(E8))),"n/a",F8/E8-1)
A19: FCF growth % (cash-paid basis) | B19: n/a | C19: =IF(OR(NOT(ISNUMBER(C10)),NOT(ISNUMBER(B10))),"n/a",C10/B10-1) | D19: =IF(OR(NOT(ISNUMBER(D10)),NOT(ISNUMBER(C10))),"n/a",D10/C10-1) | E19: =IF(OR(NOT(ISNUMBER(E10)),NOT(ISNUMBER(D10))),"n/a",E10/D10-1) | F19: =IF(OR(NOT(ISNUMBER(F10)),NOT(ISNUMBER(E10))),"n/a",F10/E10-1)
A20: Inventory growth % | B20: n/a | C20: =IF(OR(NOT(ISNUMBER(C11)),NOT(ISNUMBER(B11))),"n/a",C11/B11-1) | D20: =IF(OR(NOT(ISNUMBER(D11)),NOT(ISNUMBER(C11))),"n/a",D11/C11-1) | E20: =IF(OR(NOT(ISNUMBER(E11)),NOT(ISNUMBER(D11))),"n/a",E11/D11-1) | F20: =IF(OR(NOT(ISNUMBER(F11)),NOT(ISNUMBER(E11))),"n/a",F11/E11-1)
A21: Capex growth % | B21: n/a | C21: =IF(OR(NOT(ISNUMBER(C9)),NOT(ISNUMBER(B9))),"n/a",C9/B9-1) | D21: =IF(OR(NOT(ISNUMBER(D9)),NOT(ISNUMBER(C9))),"n/a",D9/C9-1) | E21: =IF(OR(NOT(ISNUMBER(E9)),NOT(ISNUMBER(D9))),"n/a",E9/D9-1) | F21: =IF(OR(NOT(ISNUMBER(F9)),NOT(ISNUMBER(E9))),"n/a",F9/E9-1)
A23: FY2026 BRIDGE: NET INCOME → FCF (waterfall logic, $mm) — mechanically derived from Tab 2, cash-paid capex basis
A24: Step | B24: FY2026 $mm | C24: Cumulative $mm | D24: Source
A25: Net income | B25: ='2. Historical Financials'!F16 | C25: =B25
A26: + D&A (non-cash) | B26: ='2. Historical Financials'!F31 | C26: =C25+B26
A27: +/− Other non-cash & working-capital items (plug = CFO − NI − D&A) | B27: ='2. Historical Financials'!F21-'2. Historical Financials'!F16-'2. Historical Financials'!F31 | C27: =C26+B27
A28: Subtotal → Operating cash flow (CFO) | B28: ='2. Historical Financials'!F21 | C28: =C27+B28
A29: − Capex (cash-paid, incl. intangibles) | B29: =-('2. Historical Financials'!F23+'2. Historical Financials'!F24) | C29: =C28+B29
A30: Subtotal → Free cash flow (cash-paid basis) | B30: ='2. Historical Financials'!F21-'2. Historical Financials'!F23-'2. Historical Financials'!F24 | C30: =C29+B30
A31: Memo: the single largest drag inside the 'other non-cash & WC' plug line above is the inventory build — see Tab 2 row for Inventories: FY26 balance $1,021.2mm vs FY25 $581.0mm (+75.8%), while revenue grew only +35.7% (10K26 Note 10 / Balance Sheet).
A33: WORKING CAPITAL DRAG DETAIL, FY2026 vs FY2025 (from 10-K Consolidated Statement of Cash Flows — REPORTED FACT, $mm)
A34: Cash-flow line item (change in operating assets/liabilities) | B34: FY2025 | C34: FY2026 | G34: 10K26 Consolidated Statements of Cash Flows
A35: Trade accounts receivable | E35: -165.657 | F35: -259.258
A36: Inventories | E36: -117.809 | F36: -442.901
A37: Other current/non-current assets | E37: -33.595 | F37: -108.114
A38: Trade accounts payable | E38: 194.236 | F38: 370.753
A39: Income tax payable | E39: 4.029 | F39: 55.53
A40: Accrued expenses | E40: 13.036 | F40: 16.675
A41: Other payables | E41: 11.522 | F41: 94.753
A42: Net working-capital cash impact (sum) | E42: =SUM(E35:E41) | F42: =SUM(F35:F41)
A44: READ: net income nearly tripled FY24→FY26 ($296.2mm→$473.0mm, +59.7% in the last two years alone) while FCF (cash-paid basis) fell from $364.7mm to ~$3-4mm over the same period — a collapse driven almost entirely by working-capital consumption (inventory +$442.9mm alone in FY26) outrunning the operating cash payables offset, layered on a capex ramp from $47.5mm (FY24) to $252.5mm (FY26) cash-paid.
A100: Sources: all series linked live from Tab 2 (Historical Financials), which cites 10K24/10K26 filing locations directly. Working-capital detail table sourced from 10K26 Consolidated Statements of Cash Flows.

Sheet 7. Capex & Capacity
A1: 7. CAPEX & CAPACITY
A2: Testing: ‘Fabrinet is committing long-duration capital against short-duration customer demand visibility.’
A4: CAPEX HISTORY (linked from Tab 2)
B5: FY2022 | C5: FY2023 | D5: FY2024 | E5: FY2025 | F5: FY2026 | G5: Source
A6: Cash capex (accrual basis, MD&A table) | B6: ='2. Historical Financials'!B22 | C6: ='2. Historical Financials'!C22 | D6: ='2. Historical Financials'!D22 | E6: ='2. Historical Financials'!E22 | F6: ='2. Historical Financials'!F22
A7: Cash-paid capex (PP&E + intangibles, CF stmt) | B7: ='2. Historical Financials'!B23+'2. Historical Financials'!B24 | C7: ='2. Historical Financials'!C23+'2. Historical Financials'!C24 | D7: ='2. Historical Financials'!D23+'2. Historical Financials'!D24 | E7: ='2. Historical Financials'!E23+'2. Historical Financials'!E24 | F7: ='2. Historical Financials'!F23+'2. Historical Financials'!F24
A8: Revenue (memo, linked) | B8: ='2. Historical Financials'!B6 | C8: ='2. Historical Financials'!C6 | D8: ='2. Historical Financials'!D6 | E8: ='2. Historical Financials'!E6 | F8: ='2. Historical Financials'!F6
A9: Capex / Revenue % (accrual basis) | B9: =B6/B8 | C9: =C6/C8 | D9: =D6/D8 | E9: =E6/E8 | F9: =F6/F8
A10: Capex / Revenue % (cash-paid basis) | B10: =B7/B8 | C10: =C7/C8 | D10: =D7/D8 | E10: =E7/E8 | F10: =F7/F8
A12: MANUFACTURING FOOTPRINT / FACILITY DISCLOSURES — REPORTED FACT (dollar figures only where disclosed; square footage not disclosed in filings retrieved)
A13: Item | B13: Amount | C13: Status / date | G13: Source
A14: New manufacturing building, Chonburi campus, Thailand | B14: $132.5mm (Thai baht 4.45bn) total contract price | D14: Construction began Feb 2025; $39.7mm remaining balance as of 6/26/2026 | G14: 10K26 MD&A Liquidity, p.47
A15: Manufacturing sq. footage, Chonburi expansion | B15: ~2.0 million sq ft | D15: Under construction as of 10-Q date (3/27/2026) | G15: 10K26 MD&A p.47
A16: Pathum Thani campus, Thailand | B16: Not quantified in filings retrieved | D16: Ongoing investment referenced FY2026-27 | G16: 10K26 MD&A p.48
A17: New manufacturing building, California, USA | B17: $76.9mm purchase price | D17: Acquisition COMPLETED 7/27/2026 (subsequent event, post FY26 year-end) | G17: 10K26 Note 23 'Subsequent Event', p.91
A18: Total capex commitments to third parties | B18: $108.1mm (as of 6/26/2026) vs. $164.7mm (as of 3/27/2026) | D18: Point-in-time snapshots ~3 months apart — not reconciled, shown as reported | G18: 10K26 Note 19 p.87 / 10-Q Note 14 p.27
A19: Total purchase obligations & other commitments | B19: $3.15bn (as of 6/26/2026) vs. $2.74bn (as of 3/27/2026) | D19: Inventory/component purchase commitments, generally cancelable/reschedulable per 10-Q language | G19: 10K26 Note 19 p.87 / 10-Q Note 14 p.27
A21: DEBT RAISED TO FUND EXPANSION — REPORTED FACT
A22: Item | B22: Amount | C22: Date | G22: Source
A23: Term Loan Agreement (Thai baht 2.50bn), explicitly “used to support the Company's capital expenditures” | B23: ~$75.0mm | D23: 8/17/2026 (post FY26 year-end) | G23: 10K26 Note 19, p.87
A24: 2019 Credit Facility amended — total facility increased | B24: to Thai baht 2.61bn (~$78.3mm) + $100.0mm | D24: 8/17/2026 | G24: 10K26 Note 19, p.87
A25: 2023 Credit Facility Agreement (separate facility) | B25: $30.0mm (reduced from $55.0mm in Dec-2024 qtr); $0 drawn | D25: as of 6/26/2026 / 3/27/2026 | G25: 10K26 Note 19 p.87; 10-Q Note 14 p.27
A26: FY2023 long-term borrowing (historical, fully repaid by FY24) | B26: $12.156mm outstanding at FYE23 | D26: 6/30/2023 | G26: 10K24 Balance Sheet
A29: TIMELINE OF MAJOR CAPACITY EVENTS (REPORTED FACT, chronological)
A30: Date / period | B30: Event | G30: Source
A31: FY2022-FY2024 | B31: Capex DECLINED each year: $80.5mm→$66.7mm→$49.3mm (accrual basis) — a low-capex-intensity period pre-dating the AI buildout | G31: 10K24
A32: Feb 2025 | B32: Construction begins on new ~2.0mm sq ft Chonburi manufacturing building, $132.5mm contract price | G32: 10K26 MD&A p.47
A33: FY2025 | B33: Capex nearly triples YoY to $130.7mm (accrual basis) | G33: 10K26
A34: FY2026 | B34: Capex more than doubles again to $298.9mm (accrual basis); CFO falls even as NI rises — FCF collapses to ~breakeven | G34: 10K26
A35: Jul 27, 2026 | B35: US manufacturing facility acquired for $76.9mm (subsequent event) | G35: 10K26 Note 23, p.91
A36: Aug 17, 2026 | B36: $75mm term loan signed — first new borrowing disclosed — explicitly to fund capex; credit facility expanded to $78.3mm+$100mm | G36: 10K26 Note 19, p.87
A37: FY2027 (guided) | B37: Management states FY2027 capex expected to INCREASE further vs. FY2026, driven by the California building purchase and continued Pathum Thani investment | G37: 10K26 MD&A p.48
A40: DEMAND-VISIBILITY TEST: capacity investment duration vs. disclosed order visibility
A41: Purchase obligations 'generally expected to be fulfilled within one year' | B41: 10-K Note 19 explicitly states obligations are enforceable but customers/FN retain the 'option to cancel, reschedule and/or adjust... prior to delivery' — i.e. ~1-year, adjustable visibility
A42: New Chonburi + California + Pathum Thani buildings | B42: Multi-year physical assets (manufacturing buildings, typically depreciated over years/decades) being committed against ~1-year, cancelable purchase-obligation visibility
A43: No long-term customer supply contracts disclosed | B43: 10-K discloses no multi-year MINIMUM-purchase customer commitments comparable to the capacity being built — unlike, e.g., Corning's disclosed multi-year prepaid hyperscaler deals (external, not an FN filing fact, included for contrast only)
A45: CONCLUSION ON THE TESTED THESIS: the filings support the 'long-duration capital vs. short-duration visibility' framing directionally — FN is capitalizing multi-year buildings/equipment while its own 10-K characterizes purchase obligations as ~1-year and cancelable/reschedulable. This is a reasonable reading of the disclosed facts, not a company admission — flagged as an interpretation, not a reported fact.

Sheet 8. Margin Analysis
A1: 8. MARGIN ANALYSIS
A2: Does the AI/datacenter growth cycle show structurally better margins? All figures linked from Tab 2.
A4: MARGIN HISTORY (linked from Tab 2)
B5: FY2022 | C5: FY2023 | D5: FY2024 | E5: FY2025 | F5: FY2026 | G5: Source
A6: Revenue | B6: ='2. Historical Financials'!B6 | C6: ='2. Historical Financials'!C6 | D6: ='2. Historical Financials'!D6 | E6: ='2. Historical Financials'!E6 | F6: ='2. Historical Financials'!F6
A7: Gross profit | B7: ='2. Historical Financials'!B9 | C7: ='2. Historical Financials'!C9 | D7: ='2. Historical Financials'!D9 | E7: ='2. Historical Financials'!E9 | F7: ='2. Historical Financials'!F9
A8: Gross margin % | B8: ='2. Historical Financials'!B10 | C8: ='2. Historical Financials'!C10 | D8: ='2. Historical Financials'!D10 | E8: ='2. Historical Financials'!E10 | F8: ='2. Historical Financials'!F10
A9: Operating income | B9: ='2. Historical Financials'!B14 | C9: ='2. Historical Financials'!C14 | D9: ='2. Historical Financials'!D14 | E9: ='2. Historical Financials'!E14 | F9: ='2. Historical Financials'!F14
A10: Operating margin % | B10: ='2. Historical Financials'!B15 | C10: ='2. Historical Financials'!C15 | D10: ='2. Historical Financials'!D15 | E10: ='2. Historical Financials'!E15 | F10: ='2. Historical Financials'!F15
A11: Net margin % | B11: ='2. Historical Financials'!B17 | C11: ='2. Historical Financials'!C17 | D11: ='2. Historical Financials'!D17 | E11: ='2. Historical Financials'!E17 | F11: ='2. Historical Financials'!F17
A13: INCREMENTAL MARGINS (derived: ΔProfit / ΔRevenue, year over year)
B14: FY2023 vs 22 | C14: FY2024 vs 23 | D14: FY2025 vs 24 | E14: FY2026 vs 25 | G14: Source
A15: Incremental gross margin = ΔGP / ΔRevenue | C15: =(C7-B7)/(C6-B6) | D15: =(D7-C7)/(D6-C6) | E15: =(E7-D7)/(E6-D6) | F15: =(F7-E7)/(F6-E6)
A16: Incremental operating margin = ΔOpInc / ΔRevenue | C16: =(C9-B9)/(C6-B6) | D16: =(D9-C9)/(D6-C6) | E16: =(E9-D9)/(E6-D6) | F16: =(F9-E9)/(F6-E6)
A18: READ: if the AI/datacenter cycle carried structurally better economics, incremental gross margin (the margin earned on each NEW dollar of revenue) should exceed the AVERAGE gross margin over time. Compare the incremental-margin row above to the average gross-margin row (12.3-12.7% range) directly above — the model deliberately does not pre-assert the conclusion here; read the computed cells.
A20: MARGIN RANGE SUMMARY (mechanically derived from the 5-year history above — used as the Bear/Base/Bull seed range in Tab 11)
A21: Metric | B21: Low (5-yr) | C21: Average (5-yr) | D21: High (5-yr) | E21: Latest (FY26) | G21: Source
A22: Gross margin % | B22: =MIN(C8:F8) | C22: =AVERAGE(C8:F8) | D22: =MAX(C8:F8) | E22: =F8
A23: Operating margin % | B23: =MIN(C10:F10) | C23: =AVERAGE(C10:F10) | D23: =MAX(C10:F10) | E23: =F10
A45: Sources: all figures linked live from Tab 2 (Historical Financials), citing 10K24/10K26 filing locations. Gross margin range: 12.0% (FY26, low) to 12.7% (FY23, high) — note the PEAK was FY2023, BEFORE the AI-driven capex/revenue buildout accelerated in FY25-26.

Sheet 9. Sell-Side Research
A1: 9. SELL-SIDE / ANALYST RESEARCH
A2: EXTERNAL DATA (not from FN's own filings) — cross-verified via web research 2026-09-18. Current price $386.64 used for implied upside/downside.
A4: Date | B4: Firm | C4: Analyst | D4: Rating (prev→new) | E4: PT prev | F4: PT new | G4: Implied upside/downside vs. $386.64 | H4: Reasoning | I4: Source
A5: 2026-01-22 | B5: Susquehanna | C5: Christopher Rolland | D5: Positive → Positive (maint.) | E5: 550 | F5: 570 | G5: =F5/386.64-1 | H5: Target raised into optical/AI-networking demand strength | I5: MarketBeat PT history; WebSearch corroborated
A6: 2026-02-03 | B6: B. Riley Securities | C6: Dave Kang | D6: Neutral → Neutral (maint.) | E6: 366 | F6: 452 | G6: =F6/386.64-1 | H6: Target raised; detailed rationale not accessible | I6: MarketBeat PT history; WebSearch corroborated
A7: 2026-04-16 | B7: JPMorgan | C7: Samik Chatterjee | D7: Overweight → Neutral (DOWNGRADE) | E7: 530 | F7: 700 | G7: =F7/386.64-1 | H7: Cautious on sector valuation heading into earnings; says current valuation requires investors to “dial forward” to 2028 earnings, and 2028 visibility needs to improve to support further upside | I7: StreetInsider; TipRanks/The Fly; Seeking Alpha; MarketBeat mirrors (all dated 2026-04-16)
A8: 2026-04-20 | B8: Northland Securities | C8: Tim Savageaux | D8: Buy → Buy (maint.) | E8: n/a | F8: 800 | G8: =F8/386.64-1 | H8: Reiterated bullish view on AI-optics demand | I8: MarketBeat; Investing.com; Globe and Mail
A9: 2026-05-06 | B9: Barclays | C9: Tim Long | D9: Overweight → Overweight (maint.) | E9: 548 | F9: 702 | G9: =F9/386.64-1 | H9: Raised on record fiscal Q3 FY26 revenue/EPS beat | I9: MarketBeat; Yahoo Finance
A10: 2026-07-22 | B10: Needham & Company | C10: Ryan Koontz | D10: Buy → Buy (maint.) | E10: 800 | F10: 650 | G10: =F10/386.64-1 | H10: Target CUT ahead of Q4 earnings; specific driver not independently confirmed | I10: WebSearch, 2 independent snippets
A11: 2026-08-18 | B11: JPMorgan | C11: Joseph Cardoso | D11: Neutral → Neutral (reiterated) | E11: 680 | F11: 695 | G11: =F11/386.64-1 | H11: Raised modestly despite the post-earnings sell-off; no downgrade issued on the FCF miss | I11: MarketBeat PT history table
A12: 2026-08-18 | B12: Barclays | C12: Tim Long | D12: Overweight → Overweight (reiterated) | E12: 702 | F12: 739 | G12: =F12/386.64-1 | H12: Raised despite the post-earnings drop | I12: MarketBeat PT history table
A13: 2026-08-18 | B13: Needham & Company | C13: Ryan Koontz | D13: Buy → Buy (reiterated) | E13: 650 | F13: 650 | G13: =F13/386.64-1 | H13: Reiterated post-earnings, no change | I13: MarketBeat PT history table
A14: 2026-08-18 | B14: Rosenblatt Securities | C14: Mike Genovese | D14: Buy → Buy (reiterated) | E14: 750 | F14: 750 | G14: =F14/386.64-1 | H14: Maintained bullish stance post-earnings (one other source claims $715→$750 raise — unreconciled conflict, flagged) | I14: MarketBeat PT history table vs. separate WebSearch summary
A16: ⚠ JPMorgan downgrade of 4/16/2026 (Overweight→Neutral) is the strongest-verified action, cross-corroborated across StreetInsider, TipRanks/The Fly, Seeking Alpha and MarketBeat, all dated 2026-04-16: JPMorgan cited that current valuation requires investors to ‘dial forward’ to 2028 earnings and that 2028 visibility needs to improve to support further upside.
A17: ⚠ On the post-FY26-earnings date itself (8/18/2026, the day the stock fell ~22%), JPMorgan, Barclays, Needham and Rosenblatt all REITERATED or RAISED targets rather than downgrading — no sell-side rating downgrade was found in the days immediately following the FCF-collapse earnings print. The stock's drop appears to be a buy-side reaction, not a sell-side-led repricing.
A19: NON-BANK / QUANT RATING ACTIONS (included for completeness — not sell-side banks)
A20: Date | B20: Firm | C20: Rating change | D20: Price target | H20: Note | I20: Source
A21: 2026-02-04 | B21: Wolfe Research | C21: Peer Perform → Outperform (upgrade) | D21: $540 (unchanged) | H21: Not a sell-side bank on the priority list; genuine rating upgrade, included for completeness | I21: MarketBeat / WebSearch
A22: 2026-06-15 | B22: Zacks Research (quant) | C22: Strong-Buy → Hold (downgrade) | D22: n/a | H22: Algorithmic quant rating, not a sell-side bank | I22: MarketBeat / WebSearch
A23: 2026-08-19 | B23: Fox Advisors | C23: Equal Weight → Overweight (upgrade) | D23: n/a | H23: Not on priority bank list; included for completeness | I23: MarketBeat / WebSearch
A24: 2026-09-09 | B24: Weiss Ratings (quant) | C24: Buy (B-) → Hold (C+) (downgrade) | D24: n/a | H24: Algorithmic quant rating, not a sell-side bank | I24: MarketBeat / WebSearch
A26: BANKS ON THE COMPETITION PRIORITY LIST WITH NO VERIFIABLE COVERAGE FOUND
A27: Morgan Stanley, Goldman Sachs, Bank of America, Citi, UBS, Evercore, Jefferies — searched individually; no dated rating/PT action located in accessible sources. Not assumed to be uncovered, just unverifiable here.
A29: Research caveat (from verification pass): financial-news aggregators sometimes surface stale/mismatched cached content (e.g. one TipRanks fetch returned a JPMorgan action with a 2024-vintage price target under a 2026 headline — discarded). Every row above was cross-corroborated across ≥2 independent sources or a structured MarketBeat data table, not an AI-generated summary alone.

Sheet 10. Consensus Estimates
A1: 10. CONSENSUS ESTIMATES
A2: EXTERNAL DATA. FY2026 = actual (10-K). FY2027 = verified consensus. FY2028-29 = NOT independently verifiable as genuine polled consensus — left blank rather than filled with narrative-model figures.
A4: Metric | B4: FY2026A | C4: FY2027E (consensus) | D4: FY2028E | E4: FY2029E | F4: Source / basis
A5: Revenue ($mm) | B5: ='2. Historical Financials'!F6 | C5: 6090 | D5: Not independently verifiable as polled consensus | E5: Not independently verifiable as polled consensus | F5: FY26: Tab 2 (10-K). FY27: stockanalysis.com/stocks/fn/forecast, 6 analysts, captured 2026-09-18
A6: Revenue growth % YoY | B6: ='2. Historical Financials'!F7 | C6: =C5/B5-1 | D6: n/a | E6: n/a
A7: Gross margin % | B7: ='2. Historical Financials'!F10 | C7: Not disclosed by consensus source | D7: n/a | E7: n/a
A8: Operating income ($mm) | B8: ='2. Historical Financials'!F14 | C8: Not disclosed by consensus source | D8: n/a | E8: n/a
A9: Operating margin % | B9: ='2. Historical Financials'!F15 | C9: n/a | D9: n/a | E9: n/a
A10: EBITDA ($mm) | B10: ='2. Historical Financials'!F32 | C10: n/a | D10: n/a | E10: n/a
A11: EPS, diluted ($/sh) | B11: ='2. Historical Financials'!F18 | C11: 18.16 | D11: Not independently verifiable | E11: Not independently verifiable | F11: FY27 EPS consensus: stockanalysis.com, 6 analysts
A12: EPS growth % YoY | B12: n/a | C12: =C11/B11-1 | D12: n/a | E12: n/a
A13: Operating cash flow ($mm) | B13: ='2. Historical Financials'!F21 | C13: Not disclosed by consensus source | D13: n/a | E13: n/a
A14: Capex ($mm, cash-paid) | B14: ='2. Historical Financials'!F23+'2. Historical Financials'!F24 | C14: Not disclosed by consensus source | D14: n/a | E14: n/a
A15: FCF ($mm, cash-paid basis) | B15: ='2. Historical Financials'!F26 | C15: Not disclosed by consensus source | D15: n/a | E15: n/a
A16: FCF margin % | B16: ='2. Historical Financials'!F28 | C16: n/a | D16: n/a | E16: n/a
A18: IMPLIED VALUATION AT CURRENT SHARE PRICE ($386.64, 2026-09-18)
A19: Metric | B19: FY2026A | C19: FY2027E | F19: Source / basis
A20: P/E | B20: =386.64/B11 | C20: =386.64/C11 | F20: Price / EPS. FY26A ties closely to Yahoo trailing P/E of 30.09x
A21: EV / Revenue | B21: =13200.0/B5 | C21: =13200.0/C5 | F21: EV = $13,200mm, Yahoo Finance 2026-09-18
A22: EV / EBITDA | B22: =13200.0/B9 | C22: n/a (FY27 EBITDA not verified) | F22: Yahoo shows 21.17x (stated) vs our independent calc of 24.87x on same EV/EBITDA-ttm — unreconciled, see Tab 1
A23: FCF yield | B23: =B15/14070.0 | C23: n/a (FY27 FCF not verified)
A25: ANALYST RATING BREAKDOWN & PRICE TARGETS (two conflicting source sets — shown separately, not reconciled)
A26: Rating breakdown, set 1 | B26: 7 Buy / 2 Hold / 0 Sell (9 analysts) -- stockanalysis.com / Investing.com
A27: Rating breakdown, set 2 | B27: 6 Buy / 4 Hold / 0 Sell (10 analysts) -- MarketBeat (conflicts with set 1; different analyst universe/staleness cutoff, not reconciled)
A28: Avg / High / Low PT, set 1 | B28: 734.11 | C28: 850 | D28: 598 | F28: stockanalysis.com / Investing.com
A29: Avg / High / Low PT, set 2 | B29: 649.5 | C29: 800 | D29: 452 | F29: MarketBeat
A31: Sources: stockanalysis.com/stocks/fn/forecast (FY2027 consensus, 6 analysts, captured 2026-09-18); MarketBeat and Investing.com (rating breakdowns, conflicting — likely different analyst universe/staleness cutoffs); Yahoo Finance (current EV, market cap, trailing multiples). FY2028/FY2029 consensus dollar figures were found only as a Simply Wall St narrative-model output, NOT a polled sell-side consensus, and are excluded per the no-fabrication rule.
A51: Chart deliberately stops at FY2027E: FY2028-29 consensus figures were not independently verifiable as genuine polled sell-side consensus (see note above) and are not charted.

Sheet 11. Scenario Model
A1: 11. SCENARIO MODEL
A2: Bull / Base / Bear operating model, FY2027E-FY2029E. Yellow cells are editable assumptions — every output below is a live formula.
A4: All seeds = historical MIN/AVG/MAX pulled directly from Tab 2 & Tab 8 (FY22-26 filing data), not invented. Revenue growth Bear/Bull = lowest/highest of the 4 YoY observations FY23-26; Base = their average (20.05%), which happens to land close to, but is NOT taken from, the verified FY2027 consensus growth of +31.2% (Tab 10) — shown for comparison, not used as the Base input. Gross margin, opex%, tax rate, D&A%, capex%: Bear/Bull = FY22-26 worst/best observed level; Base = 5-yr average. WC plug % = (CFO-NI-D&A)/ΔRevenue, Bear/Bull = worst/best of 4 FY23-26 observations; Base = their average. Diluted shares: held near the FY26 actual (36.252mm) with a small assumption spread.
A7: SIMPLIFICATION DISCLOSED: this model holds each assumption CONSTANT across FY27-29 (a single growth/margin/etc. rate per scenario, not a year-by-year ramp) and approximates pretax income = operating income (i.e. ignores the small historical interest-income/FX/other-income lines, which have ranged roughly $0.1-$57mm and are not forecastable from filings). This is a modeling simplification, not a filing fact — flagged explicitly per instruction.
A10: BEAR CASE
A11: Assumption (editable) | B11: Value | F11: Basis
A12: Revenue growth % (constant, FY27-29) | B12: 0.09 | F12: Historical YoY range FY23-26 (10K24/10K26)
A13: Gross margin % | B13: 0.12 | F13: Historical range FY22-26 (10K24/10K26)
A14: Opex (SG&A) % of revenue | B14: 0.033 | F14: Historical range FY22-26
A15: Effective tax rate % | B15: 0.148 | F15: Historical range FY22-26 (incl. FY26 Pillar Two effect)
A16: D&A % of revenue | B16: 0.0136 | F16: Historical range FY22-26
A17: Capex % of revenue (cash-paid basis) | B17: 0.0547 | F17: Historical range FY22-26
A18: Working-capital plug % of ΔRevenue = (CFO-NI-D&A)/ΔRev | B18: -0.233 | F18: Historical range FY23-26
A19: Diluted shares outstanding (mm) | B19: 36.5 | F19: Near FY26 actual (36.252mm)
A21: Output (formula-driven) | B21: FY2027E | C21: FY2028E | D21: FY2029E
A22: Revenue | B22: ='2. Historical Financials'!F6*(1+$B$12) | C22: =B22*(1+$B$12) | D22: =C22*(1+$B$12)
A23: Gross profit | B23: =B22*$B$13 | C23: =C22*$B$13 | D23: =D22*$B$13
A24: Operating income | B24: =B23-B22*$B$14 | C24: =C23-C22*$B$14 | D24: =D23-D22*$B$14
A25: Operating margin % | B25: =B24/B22 | C25: =C24/C22 | D25: =D24/D22
A26: Net income (= OpInc × (1−tax), simplified) | B26: =B24*(1-$B$15) | C26: =C24*(1-$B$15) | D26: =D24*(1-$B$15)
A27: Diluted EPS ($/sh) | B27: =B26/$B$19 | C27: =C26/$B$19 | D27: =D26/$B$19
A28: D&A | B28: =B22*$B$16 | C28: =C22*$B$16 | D28: =D22*$B$16
A29: Capex (cash-paid basis) | B29: =B22*$B$17 | C29: =C22*$B$17 | D29: =D22*$B$17
A30: Working-capital plug $ (see assumption above) | B30: =(B22-'2. Historical Financials'!F6)*$B$18 | C30: =(C22-B22)*$B$18 | D30: =(D22-C22)*$B$18
A31: Implied CFO = NI + D&A + WC plug | B31: =B26+B28+B30 | C31: =C26+C28+C30 | D31: =D26+D28+D30
A32: FCF = CFO − Capex | B32: =B31-B29 | C32: =C31-C29 | D32: =D31-D29
A33: FCF margin % | B33: =B32/B22 | C33: =C32/C22 | D33: =D32/D22
A36: BASE (Consensus-anchored) CASE
A37: Assumption (editable) | B37: Value | F37: Basis
A38: Revenue growth % (constant, FY27-29) | B38: 0.2005 | F38: Historical YoY range FY23-26 (10K24/10K26)
A39: Gross margin % | B39: 0.1238 | F39: Historical range FY22-26 (10K24/10K26)
A40: Opex (SG&A) % of revenue | B40: 0.026 | F40: Historical range FY22-26
A41: Effective tax rate % | B41: 0.087 | F41: Historical range FY22-26 (incl. FY26 Pillar Two effect)
A42: D&A % of revenue | B42: 0.0155 | F42: Historical range FY22-26
A43: Capex % of revenue (cash-paid basis) | B43: 0.0341 | F43: Historical range FY22-26
A44: Working-capital plug % of ΔRevenue = (CFO-NI-D&A)/ΔRev | B44: -0.065 | F44: Historical range FY23-26
A45: Diluted shares outstanding (mm) | B45: 36.2 | F45: Near FY26 actual (36.252mm)
A47: Output (formula-driven) | B47: FY2027E | C47: FY2028E | D47: FY2029E
A48: Revenue | B48: ='2. Historical Financials'!F6*(1+$B$38) | C48: =B48*(1+$B$38) | D48: =C48*(1+$B$38)
A49: Gross profit | B49: =B48*$B$39 | C49: =C48*$B$39 | D49: =D48*$B$39
...

Sheet 12. Valuation
A1: 12. VALUATION
A2: Current price $386.64 (2026-09-18, Yahoo Finance — external data). All EPS inputs link live to Tab 11.
A4: BULL / BASE / BEAR: MULTIPLE-BASED VALUATION
B5: BEAR | C5: BASE | D5: BULL
A6: FY2027E EPS ($) | B6: ='11. Scenario Model'!B27 | C6: ='11. Scenario Model'!B53 | D6: ='11. Scenario Model'!B79
A7: FY2028E EPS ($) | B7: ='11. Scenario Model'!C27 | C7: ='11. Scenario Model'!C53 | D7: ='11. Scenario Model'!C79
A8: FY2029E EPS ($) | B8: ='11. Scenario Model'!D27 | C8: ='11. Scenario Model'!D53 | D8: ='11. Scenario Model'!D79
A9: Selected P/E multiple (assumption, applied to FY2029E) | B9: 18 | C9: 30.09 | D9: 30
A10: Implied share price = FY2029E EPS × multiple | B10: =B8*B9 | C10: =C8*C9 | D10: =D8*D9
A11: Upside / (downside) vs. current price | B11: =B10/386.64-1 | C11: =C10/386.64-1 | D11: =D10/386.64-1
A13: EV/EBITDA-BASED CROSS-CHECK
B14: BEAR | C14: BASE | D14: BULL
A15: FY2029E EBITDA ($mm) = OpInc + D&A | B15: ='11. Scenario Model'!D24+'11. Scenario Model'!D28 | C15: ='11. Scenario Model'!D50+'11. Scenario Model'!D54 | D15: ='11. Scenario Model'!D76+'11. Scenario Model'!D80
A16: Selected EV/EBITDA multiple (assumption) | B16: 15 | C16: 21.17 | D16: 28
A17: Implied EV ($mm) | B17: =B15*B16 | C17: =C15*C16 | D17: =D15*D16
A18: Implied share price = (EV − net debt) / diluted shares | B18: =(B17-(4.01-875.05))/35.83 | C18: =(C17-(4.01-875.05))/35.83 | D18: =(D17-(4.01-875.05))/35.83
A20: SENSITIVITY GRID 1: Implied share price by P/E multiple × FY2029E EPS scenario
A21: P/E multiple ↓ / EPS scenario → | B21: =B8 | C21: =C8 | D21: =D8
A22: 15x | B22: =B$8*15 | C22: =C$8*15 | D22: =D$8*15
A23: 18x | B23: =B$8*18 | C23: =C$8*18 | D23: =D$8*18
A24: 20x | B24: =B$8*20 | C24: =C$8*20 | D24: =D$8*20
A25: 22x | B25: =B$8*22 | C25: =C$8*22 | D25: =D$8*22
A26: 25x | B26: =B$8*25 | C26: =C$8*25 | D26: =D$8*25
A27: 30x | B27: =B$8*30 | C27: =C$8*30 | D27: =D$8*30
